<mujoco>
    <!-- 여기 추가함 (11/9)-->
    <!-- <body mocap="true" name="robot0:mocap_base" pos="0 0 0">
        <geom conaffinity="0" contype="0" pos="0 0 0" rgba="0 0.5 0 0.7" size="0.005 0.005 0.005" type="box"></geom>
		<geom conaffinity="0" contype="0" pos="0 0 0" rgba="0 0.5 0 0.1" size="1 0.005 0.005" type="box"></geom>
		<geom conaffinity="0" contype="0" pos="0 0 0" rgba="0 0.5 0 0.1" size="0.005 1 0.001" type="box"></geom>
		<geom conaffinity="0" contype="0" pos="0 0 0" rgba="0 0.5 0 0.1" size="0.005 0.005 1" type="box"></geom>
    </body> -->

    <body mocap="true" name="robot0:mocap_arm" pos="0 0 0">
        <geom conaffinity="0" contype="0" pos="0 0 0" rgba="0 0.5 0 0.7" size="0.005 0.005 0.005" type="box"></geom>
		<geom conaffinity="0" contype="0" pos="0 0 0" rgba="0 0.5 0 0.1" size="1 0.005 0.005" type="box"></geom>
		<geom conaffinity="0" contype="0" pos="0 0 0" rgba="0 0.5 0 0.1" size="0.005 1 0.001" type="box"></geom>
		<geom conaffinity="0" contype="0" pos="0 0 0" rgba="0 0.5 0 0.1" size="0.005 0.005 1" type="box"></geom>
    </body>


    <body name="robot0:base_link" pos="0 0 0.14493" >
        <joint armature="0.0001" axis="1 0 0" damping="1e+11" name="robot0:slide0" pos="0 0 0" type="slide" limited="false"></joint>
		<joint armature="0.0001" axis="0 1 0" damping="1e+11" name="robot0:slide1" pos="0 0 0" type="slide" limited="false"></joint>
		<joint armature="0.0001" axis="0 0 1" damping="1e+0" name="robot0:slide2" pos="0 0 0" type="slide" limited="false"></joint>
        
        <site name="robot0:base_link" pos="0.0 0.0 0.0" size="0.02" rgba="1 0 0 1" type="sphere"></site>
        
        <geom name="base_link_visual" type="mesh" contype="0" conaffinity="0" group="1" mesh="mobile_base_link" />
        <geom name="base_link_collision" size="0.4937 0.28545 0.061875" type="box" />
        

		
		<inertial diaginertia="1.2869 1.2236 0.9868" mass="70.1294" pos="-0.0036 0 0.0014" quat="0.7605 -0.0133 -0.0061 0.6491"></inertial>

        <!-- husky mobile robot body -->
        <geom size="0.39496 0.28545 0.061875" pos="0 0 0.185625" type="box" />
        <geom type="mesh" contype="0" conaffinity="0" group="1" mesh="top_chassis" class="husky:orange" />

        <geom pos="0.48 0 0.091" type="mesh" contype="0" conaffinity="0" group="1" mesh="bumper" />
        <geom pos="-0.48 0 0.091" quat="1.32679e-06 0 0 1" type="mesh" contype="0" conaffinity="0" group="1" mesh="bumper" />

        <!-- This part will collide with arm, leading to a range (-2., 0.75), not (-3.14, 3.14) 2020.01.17-->
        <geom pos="0 0 0.225" type="mesh" contype="0" conaffinity="0" group="1" mesh="dual_arm_bulkhead" />

        <!-- husky wheels -->
        <body name="front_left_wheel_link" pos="0.256 0.2854 0.03282">
            <inertial pos="0 0 0" quat="0.5 0.5 -0.5 0.5" mass="200.637" diaginertia="0.04411 0.02467 0.02467" />
            <geom type="mesh" contype="0" conaffinity="0" group="1" mesh="wheel" class="wheel"/>
            <geom size="0.17775 0.05715" quat="0.707107 0.707106 0 0" type="cylinder" />
        </body>

        <body name="front_right_wheel_link" pos="0.256 -0.2854 0.03282">
            <inertial pos="0 0 0" quat="0.5 0.5 -0.5 0.5" mass="200.637" diaginertia="0.04411 0.02467 0.02467" />
            <geom type="mesh" contype="0" conaffinity="0" group="1" mesh="wheel" class="wheel"/>
            <geom size="0.17775 0.05715" quat="0.707107 0.707106 0 0" type="cylinder" />
        </body>

        <body name="rear_left_wheel_link" pos="-0.256 0.2854 0.03282">
            <inertial pos="0 0 0" quat="0.5 0.5 -0.5 0.5" mass="200.637" diaginertia="0.04411 0.02467 0.02467" />
            <geom type="mesh" contype="0" conaffinity="0" group="1" mesh="wheel" class="wheel"/>
            <geom size="0.17775 0.05715" quat="0.707107 0.707106 0 0" type="cylinder" />
        </body>

        <body name="rear_right_wheel_link" pos="-0.256 -0.2854 0.03282">
            <inertial pos="0 0 0" quat="0.5 0.5 -0.5 0.5" mass="200.637" diaginertia="0.04411 0.02467 0.02467" />
            <geom type="mesh" contype="0" conaffinity="0" group="1" mesh="wheel" class="wheel"/>
            <geom size="0.17775 0.05715" quat="0.707107 0.707106 0 0" type="cylinder" />
        </body>

        <body name="link0" pos="0.25 0.0 0.42">
            <geom name="bb" type="mesh" mesh="link_base" material="robot0:base_mat" rgba="1 1 1 1"/>
            <body name="link1" pos="0 0 0.267">
                <inertial pos="-0.0042142 0.02821 -0.0087788" quat="0.917781 -0.277115 0.0606681 0.277858" mass="0.42603" diaginertia="0.00144551 0.00137757 0.000823511" />
                <joint name="robot0:shoulder_pan_joint" pos="0 0 0" axis="0 0 1" limited="true" range="-6.28319 6.28319" damping="10" frictionloss="1" />
                <geom name="j1" type="mesh" mesh="link1" material="robot0:arm_mat" rgba="1 1 1 1"/>
                <body name="link2" pos="0 0 0" quat="0.707105 -0.707108 0 0">
                    <inertial pos="-3.3178e-05 -0.12849 0.026337" quat="0.447793 0.894132 -0.00224061 0.00218314" mass="0.56095" diaginertia="0.00319151 0.00311598 0.000980804" />
                    <joint name="robot0:shoulder_lift_joint" pos="0 0 0" axis="0 0 1" limited="true" range="-2.059 2.0944" damping="10" frictionloss="1" />
                    <geom name="j2"  type="mesh"  mesh="link2" material="robot0:head_mat" rgba="1 1 1 1"/>
                    <body name="link3" pos="0 -0.293 0" quat="0.707105 0.707108 0 0">
                        <inertial pos="0.04223 -0.023258 -0.0096674" quat="0.883205 0.339803 0.323238 0.000542237" mass="0.44463" diaginertia="0.00133227 0.00119126 0.000780475" />
                        <joint name="robot0:upperarm_roll_joint" pos="0 0 0" axis="0 0 1" limited="true" range="-6.28319 6.28319" damping="5" frictionloss="1" />
                        <geom name="j3" type="mesh" mesh="link3" material="robot0:gripper_mat" rgba="1 1 1 1"/>
                        <body name="link4" pos="0.0525 0 0" quat="0.707105 0.707108 0 0">
                            <inertial pos="0.067148 -0.10732 0.024479" quat="0.0654142 0.483317 -0.738663 0.465298" mass="0.52387" diaginertia="0.00288984 0.00282705 0.000894409" />
                            <joint name="robot0:elbow_flex_joint" pos="0 0 0" axis="0 0 1" limited="true" range="-0.19198 3.927" damping="5" frictionloss="1" />
                            <geom name="j4" type="mesh" mesh="link4" material="robot0:arm_mat" rgba="1 1 1 1"/>
                            <body name="link5" pos="0.0775 -0.3425 0" quat="0.707105 0.707108 0 0">
                                <inertial pos="-0.00023397 0.036705 -0.080064" quat="0.981064 -0.19003 0.00637998 0.0369004" mass="0.18554" diaginertia="0.00099553 0.000988613 0.000247126" />
                                <joint name="robot0:forearm_roll_joint" pos="0 0 0" axis="0 0 1" limited="true" range="-6.28319 6.28319" damping="5" frictionloss="1" />
                                <geom name="j5" type="mesh"  material="robot0:gripper_mat" rgba="1 1 1 1" mesh="link5" />
                                <body name="link6" pos="0 0 0" quat="0.707105 0.707108 0 0">
                                    <inertial pos="0.058911 0.028469 0.0068428" quat="-0.188705 0.793535 0.166088 0.554173" mass="0.31344" diaginertia="0.000827892 0.000768871 0.000386708" />
                                    <joint name="robot0:wrist_flex_joint" pos="0 0 0" axis="0 0 1" limited="true" range="-1.69297 3.14159" damping="2" frictionloss="1" />
                                    <geom name="j6" type="mesh" material="robot0:gripper_mat" rgba="1 1 1 1" mesh="link6" />

                                    <body name="link7" pos="0.076 0.097 0" quat="0.707105 -0.707108 0 0">
                                        <inertial pos="-0.000420033 -0.00287433 0.0257078" quat="0.999372 -0.0349129 -0.00605634 0.000551744" mass="0.85624" diaginertia="0.00137671 0.00118744 0.000514968" />
                                        <joint name="robot0:wrist_roll_joint" pos="0 0 0" axis="0 0 1" limited="true" range="-6.28319 6.28319" damping="2" frictionloss="1" />
                                        <geom name="j8" material="robot0:gripper_mat" type="mesh" rgba="0.753 0.753 0.753 1" mesh="link7" />
                                        <!--<geom name="j8" material="robot0:gripper_mat" type="mesh" rgba="0 0 0 1" mesh="link7" />-->
                                        <geom name="j9" material="robot0:gripper_mat" type="mesh" rgba="1 1 1 1" mesh="base_link" />
                                        <!--<geom name="j9" material="robot0:gripper_mat" type="mesh" rgba="0 0 0 1" mesh="base_link" />-->

                                        <camera mode="fixed" name="first_person" pos="0.15 -0.05 -0.25" euler="3.14159 0.2 -1.5708" fovy="25"/>




                                        <body name="left_outer_knuckle" pos="0 0.035 0.059098">
                                            <inertial pos="0 0.021559 0.015181" quat="0.47789 0.87842 0 0" mass="0.033618" diaginertia="1.9111e-05 1.79089e-05 1.90167e-06" />
                                            <!-- <joint name="robot0:l_gripper_finger_joint_No" pos="0 0 0" axis="1 0 0" limited="true" range="0 0.85" /> -->
                                            <geom type="mesh" rgba="0 0 0 1" conaffinity="1" contype="0"  mesh="left_outer_knuckle" />
                                            <body name="left_finger" pos="0 0.035465 0.042039">
                                                <inertial pos="0 -0.016413 0.029258" quat="0.697634 0.115353 -0.115353 0.697634" mass="0.048304" diaginertia="1.88037e-05 1.7493e-05 3.56792e-06" />
                                                <joint name="robot0:l_gripper_finger_joint" pos="0 0 0" axis="-1 0 0" limited="true" range="0 0.85" />
                                                <geom name="j10" material="robot0:gripper_finger_mat" type="mesh" rgba="0 0 0 1" conaffinity="3" contype="2"  mesh="left_finger" friction='1.5 1.5 1.5' solref='0.01 1' solimp='0.99 0.99 0.01'/>

                                                    <body name="right_hand" pos="0 -0.03 0.05" quat="-0.7071 0 0 0.7071">


                                                </body>

                                            </body>
                                        </body>

                                        <body name="right_outer_knuckle" pos="0 -0.035 0.059098">
                                            <inertial pos="0 -0.021559 0.015181" quat="0.87842 0.47789 0 0" mass="0.033618" diaginertia="1.9111e-05 1.79089e-05 1.90167e-06" />
                                            <!-- <joint name="robot0:r_gripper_finger_joint_No" pos="0 0 0" axis="-1 0 0" limited="true" range="0 0.85" /> -->
                                            <geom type="mesh" rgba="0 0 0 1" conaffinity="1" contype="0"  mesh="right_outer_knuckle" />
                                            <body name="right_finger" pos="0 -0.035465 0.042039">
                                                <inertial pos="0 0.016413 0.029258" quat="0.697634 -0.115356 0.115356 0.697634" mass="0.048304" diaginertia="1.88038e-05 1.7493e-05 3.56779e-06" />
                                                <joint name="robot0:r_gripper_finger_joint" pos="0 0 0" axis="1 0 0" limited="true" range="0 0.85" />
                                                <geom name="j11" material="robot0:gripper_finger_mat" type="mesh" rgba="0 0 0 1" conaffinity="3" contype="2" mesh="right_finger" friction='1.5 1.5 1.5' solref='0.01 1' solimp='0.99 0.99 0.01'/>

                                                <body name="left_hand" pos="0 0.03 0.05" quat="-0.7071 0 0 0.7071">
                                                </body>
                                            </body>
                                        </body>

                                        <site name="robot0:grip" pos="0 0.0 0.13" rgba="1 0 0 1" size="0.05" type="sphere"> </site>
                                    </body>
                                </body>
                            </body>
                        </body>
                    </body>
                </body>
            </body>
        </body>
    </body>
</mujoco>
