<mujoco>

	<body mocap="true" name="gripper_r:mocap" pos="0 0 0" >
		<geom conaffinity="0" contype="0" pos="0 0. 0" rgba="0.0 0.5 0.0 0.5" size="0.005 0.005 0.005" type="box" group="1"></geom>
		<geom conaffinity="0" contype="0" pos="0 0. 0" rgba="1.0 0.0 0.0 0.5" size="0.15 0.005 0.005" type="box" group="1"></geom>
		<geom conaffinity="0" contype="0" pos="0 0. 0" rgba="0.0 1.0 0.0 0.5" size="0.005 0.15 0.005" type="box" group="1"></geom>
		<geom conaffinity="0" contype="0" pos="0 0. 0" rgba="0.0 0.0 1.0 0.5" size="0.005 0.005 0.15" type="box" group="1"></geom>
	</body>
	<body mocap="true" name="gripper_l:mocap" pos="0 0 0" >
		<geom conaffinity="0" contype="0" pos="0 0.1 0" rgba="0.0 0.5 0.0 0.5" size="0.005 0.005 0.005" type="box"></geom>
		<geom conaffinity="0" contype="0" pos="0 0.1 0" rgba="1.0 0.0 0.0 0.5" size="1 0.005 0.005" type="box"></geom>
		<geom conaffinity="0" contype="0" pos="0 0.1 0" rgba="0.0 1.0 0.0 0.5" size="0.005 1 0.005" type="box"></geom>
		<geom conaffinity="0" contype="0" pos="0 0.1 0" rgba="0.0 0.0 1.0 0.5" size="0.005 0.005 1" type="box"></geom>
	</body>

    <!-- 여기 추가함 (11/9)-->
    <body mocap="true" name="robot0:mocap" pos="0 0 0">
        <geom conaffinity="0" contype="0" pos="0 0 0" rgba="0 0.5 0 0.7" size="0.005 0.005 0.005" type="box"></geom>
		<geom conaffinity="0" contype="0" pos="0 0 0" rgba="0 0.5 0 0.1" size="1 0.005 0.005" type="box"></geom>
		<geom conaffinity="0" contype="0" pos="0 0 0" rgba="0 0.5 0 0.1" size="0.005 1 0.001" type="box"></geom>
		<geom conaffinity="0" contype="0" pos="0 0 0" rgba="0 0.5 0 0.1" size="0.005 0.005 1" type="box"></geom>
    </body>



    

    
    <body name="robot0:base_link" pos="0 0 0.0" >
    <!-- <body name="robot0:base_link" pos="0 0 0.061875" > -->
        <joint armature="0.0001" axis="1 0 0" damping="1e+11" name="robot0:slide0" pos="0 0 0" type="slide" limited="true" range="-6.28319 6.28319" frictionloss="100"></joint>
		<joint armature="0.0001" axis="0 1 0" damping="1e+11" name="robot0:slide1" pos="0 0 0" type="slide" limited="true" range="-6.28319 6.28319" frictionloss="1"></joint>
		<joint armature="0.0001" axis="0 0 1" damping="1e+0" name="robot0:slide2" pos="0 0 0" type="slide" limited="true" range="-6.28319 6.28319" frictionloss="1"></joint>

        <!-- 이거 아래 오류뜨는 이유 찾기 !! gym 에서는 이 구조로 되있다.
        <joint armature="0.0001" axis="1 0 0" damping="1e+11" name="robot0:slide0" pos="0 0 0" type="slide"></joint>
		<joint armature="0.0001" axis="0 1 0" damping="1e+11" name="robot0:slide1" pos="0 0 0" type="slide"></joint>
		<joint armature="0.0001" axis="0 0 1" damping="1e+0" name="robot0:slide2" pos="0 0 0" type="slide"></joint> -->


        <geom name="base_link_visual" type="mesh" contype="0" conaffinity="0" group="1" mesh="mobile_base_link" />
        <geom name="base_link_collision" size="0.4937 0.28545 0.061875" type="box" />
        

		
		<inertial diaginertia="1.2869 1.2236 0.9868" mass="70.1294" pos="-0.0036 0 0.0014" quat="0.7605 -0.0133 -0.0061 0.6491"></inertial>

		<!-- control the husky base -->
		<!-- <joint name="base_x_slide_joint" type="slide" pos="0 0 0" axis="1 0 0" limited="true" range="-10 10" damping="15000"/>
        <joint name="base_z_hinge_joint" type="hinge" pos="0 0 0" axis="0 0 1" limited="true" range="-6.28 6.28" damping="10000"/> -->
        <!-- <joint name="base_x_slide_joint" type="slide" pos="0 0 0" axis="1 0 0" limited="true" range="-1 0.5" damping="100"/> -->

        <!-- husky mobile robot body -->
        <geom size="0.39496 0.28545 0.061875" pos="0 0 0.185625" type="box" />
        <geom type="mesh" contype="0" conaffinity="0" group="1" mesh="top_chassis" class="husky:orange" />

        <geom pos="0.48 0 0.091" type="mesh" contype="0" conaffinity="0" group="1" mesh="bumper" />
        <geom pos="-0.48 0 0.091" quat="1.32679e-06 0 0 1" type="mesh" contype="0" conaffinity="0" group="1" mesh="bumper" />

        <!-- This part will collide with arm, leading to a range (-2., 0.75), not (-3.14, 3.14) 2020.01.17-->
        <geom pos="0 0 0.225" type="mesh" contype="0" conaffinity="0" group="1" mesh="dual_arm_bulkhead" />
        <!-- <geom pos="0 0 0.225" type="mesh" mesh="dual_arm_bulkhead" /> -->

        <!-- husky wheels -->
        <body name="front_left_wheel_link" pos="0.256 0.2854 0.03282">
            <inertial pos="0 0 0" quat="0.5 0.5 -0.5 0.5" mass="200.637" diaginertia="0.04411 0.02467 0.02467" />
            <!-- <joint name="front_left_wheel" pos="0 0 0" axis="0 1 0" limited="true" range="-6.28319 6.28319" damping="10" frictionloss="1"/> -->
            <geom type="mesh" contype="0" conaffinity="0" group="1" mesh="wheel" class="wheel"/>
            <geom size="0.17775 0.05715" quat="0.707107 0.707106 0 0" type="cylinder" />
        </body>
        <body name="front_right_wheel_link" pos="0.256 -0.2854 0.03282">
            <inertial pos="0 0 0" quat="0.5 0.5 -0.5 0.5" mass="200.637" diaginertia="0.04411 0.02467 0.02467" />
            <!-- <joint name="front_right_wheel" pos="0 0 0" axis="0 1 0" limited="true" range="-6.28319 6.28319" damping="10" frictionloss="1"/> -->
            <geom type="mesh" contype="0" conaffinity="0" group="1" mesh="wheel" class="wheel"/>
            <geom size="0.17775 0.05715" quat="0.707107 0.707106 0 0" type="cylinder" />
        </body>
        <body name="rear_left_wheel_link" pos="-0.256 0.2854 0.03282">
            <inertial pos="0 0 0" quat="0.5 0.5 -0.5 0.5" mass="200.637" diaginertia="0.04411 0.02467 0.02467" />
            <!-- <joint name="rear_left_wheel" pos="0 0 0" axis="0 1 0" limited="true" range="-6.28319 6.28319" damping="10" frictionloss="1"/> -->
            <geom type="mesh" contype="0" conaffinity="0" group="1" mesh="wheel" class="wheel"/>
            <geom size="0.17775 0.05715" quat="0.707107 0.707106 0 0" type="cylinder" />
        </body>
        <body name="rear_right_wheel_link" pos="-0.256 -0.2854 0.03282">
            <inertial pos="0 0 0" quat="0.5 0.5 -0.5 0.5" mass="200.637" diaginertia="0.04411 0.02467 0.02467" />
            <!-- <joint name="rear_right_wheel" pos="0 0 0" axis="0 1 0" limited="true" range="-6.28319 6.28319" damping="10" frictionloss="1"/> -->
            <geom type="mesh" contype="0" conaffinity="0" group="1" mesh="wheel" class="wheel"/>
            <geom size="0.17775 0.05715" quat="0.707107 0.707106 0 0" type="cylinder" />
        </body>

        <include file="panda.xml"></include>

    </body>
</mujoco>
